[2021-11-21 11:10:10,917: INFO: 01_base_model_creation]: 
********************
[2021-11-21 11:10:10,918: INFO: 01_base_model_creation]: >>>>> stage creating base model started <<<<<
[2021-11-21 11:10:10,918: ERROR: 01_base_model_creation]: main() missing 1 required positional argument: 'params_path'
Traceback (most recent call last):
  File "src/01_base_model_creation.py", line 67, in <module>
    main(config_path=parsed_args.config)
TypeError: main() missing 1 required positional argument: 'params_path'
[2021-11-21 11:10:24,301: INFO: 01_base_model_creation]: 
********************
[2021-11-21 11:10:24,302: INFO: 01_base_model_creation]: >>>>> stage creating base model started <<<<<
[2021-11-21 11:10:24,303: INFO: common]: yaml file: configs/config.yaml loaded successfully
[2021-11-21 11:10:28,389: INFO: 01_base_model_creation]: >>>>> stage creating base model completed!<<<<<

[2021-11-21 11:21:50,290: INFO: 01_base_model_creation]: 
********************
[2021-11-21 11:21:50,304: INFO: 01_base_model_creation]: >>>>> stage creating base model started <<<<<
[2021-11-21 11:21:50,307: INFO: common]: yaml file: configs/config.yaml loaded successfully
[2021-11-21 11:21:56,033: ERROR: 01_base_model_creation]: in user code:

    File "C:\Users\Sasmitabhoi\anaconda3\envs\Transfer-Learning\lib\site-packages\keras\engine\training.py", line 878, in train_function  *
        return step_function(self, iterator)
    File "C:\Users\Sasmitabhoi\anaconda3\envs\Transfer-Learning\lib\site-packages\keras\engine\training.py", line 867, in step_function  **
        outputs = model.distribute_strategy.run(run_step, args=(data,))
    File "C:\Users\Sasmitabhoi\anaconda3\envs\Transfer-Learning\lib\site-packages\keras\engine\training.py", line 860, in run_step  **
        outputs = model.train_step(data)
    File "C:\Users\Sasmitabhoi\anaconda3\envs\Transfer-Learning\lib\site-packages\keras\engine\training.py", line 810, in train_step
        y, y_pred, sample_weight, regularization_losses=self.losses)
    File "C:\Users\Sasmitabhoi\anaconda3\envs\Transfer-Learning\lib\site-packages\keras\engine\compile_utils.py", line 184, in __call__
        self.build(y_pred)
    File "C:\Users\Sasmitabhoi\anaconda3\envs\Transfer-Learning\lib\site-packages\keras\engine\compile_utils.py", line 133, in build
        self._losses = tf.nest.map_structure(self._get_loss_object, self._losses)
    File "C:\Users\Sasmitabhoi\anaconda3\envs\Transfer-Learning\lib\site-packages\keras\engine\compile_utils.py", line 273, in _get_loss_object
        loss = losses_mod.get(loss)
    File "C:\Users\Sasmitabhoi\anaconda3\envs\Transfer-Learning\lib\site-packages\keras\losses.py", line 2134, in get
        return deserialize(identifier)
    File "C:\Users\Sasmitabhoi\anaconda3\envs\Transfer-Learning\lib\site-packages\keras\losses.py", line 2093, in deserialize
        printable_module_name='loss function')
    File "C:\Users\Sasmitabhoi\anaconda3\envs\Transfer-Learning\lib\site-packages\keras\utils\generic_utils.py", line 709, in deserialize_keras_object
        f'Unknown {printable_module_name}: {object_name}. Please ensure '

    ValueError: Unknown loss function: sparse. Please ensure this object is passed to the `custom_objects` argument. See https://www.tensorflow.org/guide/keras/save_and_serialize#registering_the_custom_object for details.
Traceback (most recent call last):
  File "src/01_base_model_creation.py", line 82, in <module>
    main(config_path=parsed_args.config)
  File "src/01_base_model_creation.py", line 62, in main
    verbose=2)
  File "C:\Users\Sasmitabhoi\anaconda3\envs\Transfer-Learning\lib\site-packages\keras\utils\traceback_utils.py", line 67, in error_handler
    raise e.with_traceback(filtered_tb) from None
  File "C:\Users\Sasmitabhoi\anaconda3\envs\Transfer-Learning\lib\site-packages\tensorflow\python\framework\func_graph.py", line 1129, in autograph_handler
    raise e.ag_error_metadata.to_exception(e)
ValueError: in user code:

    File "C:\Users\Sasmitabhoi\anaconda3\envs\Transfer-Learning\lib\site-packages\keras\engine\training.py", line 878, in train_function  *
        return step_function(self, iterator)
    File "C:\Users\Sasmitabhoi\anaconda3\envs\Transfer-Learning\lib\site-packages\keras\engine\training.py", line 867, in step_function  **
        outputs = model.distribute_strategy.run(run_step, args=(data,))
    File "C:\Users\Sasmitabhoi\anaconda3\envs\Transfer-Learning\lib\site-packages\keras\engine\training.py", line 860, in run_step  **
        outputs = model.train_step(data)
    File "C:\Users\Sasmitabhoi\anaconda3\envs\Transfer-Learning\lib\site-packages\keras\engine\training.py", line 810, in train_step
        y, y_pred, sample_weight, regularization_losses=self.losses)
    File "C:\Users\Sasmitabhoi\anaconda3\envs\Transfer-Learning\lib\site-packages\keras\engine\compile_utils.py", line 184, in __call__
        self.build(y_pred)
    File "C:\Users\Sasmitabhoi\anaconda3\envs\Transfer-Learning\lib\site-packages\keras\engine\compile_utils.py", line 133, in build
        self._losses = tf.nest.map_structure(self._get_loss_object, self._losses)
    File "C:\Users\Sasmitabhoi\anaconda3\envs\Transfer-Learning\lib\site-packages\keras\engine\compile_utils.py", line 273, in _get_loss_object
        loss = losses_mod.get(loss)
    File "C:\Users\Sasmitabhoi\anaconda3\envs\Transfer-Learning\lib\site-packages\keras\losses.py", line 2134, in get
        return deserialize(identifier)
    File "C:\Users\Sasmitabhoi\anaconda3\envs\Transfer-Learning\lib\site-packages\keras\losses.py", line 2093, in deserialize
        printable_module_name='loss function')
    File "C:\Users\Sasmitabhoi\anaconda3\envs\Transfer-Learning\lib\site-packages\keras\utils\generic_utils.py", line 709, in deserialize_keras_object
        f'Unknown {printable_module_name}: {object_name}. Please ensure '

    ValueError: Unknown loss function: sparse. Please ensure this object is passed to the `custom_objects` argument. See https://www.tensorflow.org/guide/keras/save_and_serialize#registering_the_custom_object for details.

[2021-11-21 11:27:32,999: INFO: 01_base_model_creation]: 
********************
[2021-11-21 11:27:32,999: INFO: 01_base_model_creation]: >>>>> stage creating base model started <<<<<
[2021-11-21 11:27:33,001: INFO: common]: yaml file: configs/config.yaml loaded successfully
[2021-11-21 11:27:34,947: INFO: 01_base_model_creation]: >>>>> stage creating base model completed!<<<<<

[2021-11-21 11:30:25,893: INFO: 01_base_model_creation]: 
********************
[2021-11-21 11:30:25,893: INFO: 01_base_model_creation]: >>>>> stage creating base model started <<<<<
[2021-11-21 11:30:25,894: INFO: common]: yaml file: configs/config.yaml loaded successfully
[2021-11-21 11:30:28,148: ERROR: 01_base_model_creation]: in user code:

    File "C:\Users\Sasmitabhoi\anaconda3\envs\Transfer-Learning\lib\site-packages\keras\engine\training.py", line 878, in train_function  *
        return step_function(self, iterator)
    File "C:\Users\Sasmitabhoi\anaconda3\envs\Transfer-Learning\lib\site-packages\keras\engine\training.py", line 867, in step_function  **
        outputs = model.distribute_strategy.run(run_step, args=(data,))
    File "C:\Users\Sasmitabhoi\anaconda3\envs\Transfer-Learning\lib\site-packages\keras\engine\training.py", line 860, in run_step  **
        outputs = model.train_step(data)
    File "C:\Users\Sasmitabhoi\anaconda3\envs\Transfer-Learning\lib\site-packages\keras\engine\training.py", line 810, in train_step
        y, y_pred, sample_weight, regularization_losses=self.losses)
    File "C:\Users\Sasmitabhoi\anaconda3\envs\Transfer-Learning\lib\site-packages\keras\engine\compile_utils.py", line 184, in __call__
        self.build(y_pred)
    File "C:\Users\Sasmitabhoi\anaconda3\envs\Transfer-Learning\lib\site-packages\keras\engine\compile_utils.py", line 133, in build
        self._losses = tf.nest.map_structure(self._get_loss_object, self._losses)
    File "C:\Users\Sasmitabhoi\anaconda3\envs\Transfer-Learning\lib\site-packages\keras\engine\compile_utils.py", line 273, in _get_loss_object
        loss = losses_mod.get(loss)
    File "C:\Users\Sasmitabhoi\anaconda3\envs\Transfer-Learning\lib\site-packages\keras\losses.py", line 2134, in get
        return deserialize(identifier)
    File "C:\Users\Sasmitabhoi\anaconda3\envs\Transfer-Learning\lib\site-packages\keras\losses.py", line 2093, in deserialize
        printable_module_name='loss function')
    File "C:\Users\Sasmitabhoi\anaconda3\envs\Transfer-Learning\lib\site-packages\keras\utils\generic_utils.py", line 709, in deserialize_keras_object
        f'Unknown {printable_module_name}: {object_name}. Please ensure '

    ValueError: Unknown loss function: sparse. Please ensure this object is passed to the `custom_objects` argument. See https://www.tensorflow.org/guide/keras/save_and_serialize#registering_the_custom_object for details.
Traceback (most recent call last):
  File "src/01_base_model_creation.py", line 82, in <module>
    main(config_path=parsed_args.config)
  File "src/01_base_model_creation.py", line 62, in main
    verbose=2)
  File "C:\Users\Sasmitabhoi\anaconda3\envs\Transfer-Learning\lib\site-packages\keras\utils\traceback_utils.py", line 67, in error_handler
    raise e.with_traceback(filtered_tb) from None
  File "C:\Users\Sasmitabhoi\anaconda3\envs\Transfer-Learning\lib\site-packages\tensorflow\python\framework\func_graph.py", line 1129, in autograph_handler
    raise e.ag_error_metadata.to_exception(e)
ValueError: in user code:

    File "C:\Users\Sasmitabhoi\anaconda3\envs\Transfer-Learning\lib\site-packages\keras\engine\training.py", line 878, in train_function  *
        return step_function(self, iterator)
    File "C:\Users\Sasmitabhoi\anaconda3\envs\Transfer-Learning\lib\site-packages\keras\engine\training.py", line 867, in step_function  **
        outputs = model.distribute_strategy.run(run_step, args=(data,))
    File "C:\Users\Sasmitabhoi\anaconda3\envs\Transfer-Learning\lib\site-packages\keras\engine\training.py", line 860, in run_step  **
        outputs = model.train_step(data)
    File "C:\Users\Sasmitabhoi\anaconda3\envs\Transfer-Learning\lib\site-packages\keras\engine\training.py", line 810, in train_step
        y, y_pred, sample_weight, regularization_losses=self.losses)
    File "C:\Users\Sasmitabhoi\anaconda3\envs\Transfer-Learning\lib\site-packages\keras\engine\compile_utils.py", line 184, in __call__
        self.build(y_pred)
    File "C:\Users\Sasmitabhoi\anaconda3\envs\Transfer-Learning\lib\site-packages\keras\engine\compile_utils.py", line 133, in build
        self._losses = tf.nest.map_structure(self._get_loss_object, self._losses)
    File "C:\Users\Sasmitabhoi\anaconda3\envs\Transfer-Learning\lib\site-packages\keras\engine\compile_utils.py", line 273, in _get_loss_object
        loss = losses_mod.get(loss)
    File "C:\Users\Sasmitabhoi\anaconda3\envs\Transfer-Learning\lib\site-packages\keras\losses.py", line 2134, in get
        return deserialize(identifier)
    File "C:\Users\Sasmitabhoi\anaconda3\envs\Transfer-Learning\lib\site-packages\keras\losses.py", line 2093, in deserialize
        printable_module_name='loss function')
    File "C:\Users\Sasmitabhoi\anaconda3\envs\Transfer-Learning\lib\site-packages\keras\utils\generic_utils.py", line 709, in deserialize_keras_object
        f'Unknown {printable_module_name}: {object_name}. Please ensure '

    ValueError: Unknown loss function: sparse. Please ensure this object is passed to the `custom_objects` argument. See https://www.tensorflow.org/guide/keras/save_and_serialize#registering_the_custom_object for details.

[2021-11-21 11:32:09,595: INFO: 01_base_model_creation]: 
********************
[2021-11-21 11:32:09,596: INFO: 01_base_model_creation]: >>>>> stage creating base model started <<<<<
[2021-11-21 11:32:09,597: INFO: common]: yaml file: configs/config.yaml loaded successfully
[2021-11-21 11:32:11,999: ERROR: 01_base_model_creation]: in user code:

    File "C:\Users\Sasmitabhoi\anaconda3\envs\Transfer-Learning\lib\site-packages\keras\engine\training.py", line 878, in train_function  *
        return step_function(self, iterator)
    File "C:\Users\Sasmitabhoi\anaconda3\envs\Transfer-Learning\lib\site-packages\keras\engine\training.py", line 867, in step_function  **
        outputs = model.distribute_strategy.run(run_step, args=(data,))
    File "C:\Users\Sasmitabhoi\anaconda3\envs\Transfer-Learning\lib\site-packages\keras\engine\training.py", line 860, in run_step  **
        outputs = model.train_step(data)
    File "C:\Users\Sasmitabhoi\anaconda3\envs\Transfer-Learning\lib\site-packages\keras\engine\training.py", line 810, in train_step
        y, y_pred, sample_weight, regularization_losses=self.losses)
    File "C:\Users\Sasmitabhoi\anaconda3\envs\Transfer-Learning\lib\site-packages\keras\engine\compile_utils.py", line 184, in __call__
        self.build(y_pred)
    File "C:\Users\Sasmitabhoi\anaconda3\envs\Transfer-Learning\lib\site-packages\keras\engine\compile_utils.py", line 133, in build
        self._losses = tf.nest.map_structure(self._get_loss_object, self._losses)
    File "C:\Users\Sasmitabhoi\anaconda3\envs\Transfer-Learning\lib\site-packages\keras\engine\compile_utils.py", line 273, in _get_loss_object
        loss = losses_mod.get(loss)
    File "C:\Users\Sasmitabhoi\anaconda3\envs\Transfer-Learning\lib\site-packages\keras\losses.py", line 2134, in get
        return deserialize(identifier)
    File "C:\Users\Sasmitabhoi\anaconda3\envs\Transfer-Learning\lib\site-packages\keras\losses.py", line 2093, in deserialize
        printable_module_name='loss function')
    File "C:\Users\Sasmitabhoi\anaconda3\envs\Transfer-Learning\lib\site-packages\keras\utils\generic_utils.py", line 709, in deserialize_keras_object
        f'Unknown {printable_module_name}: {object_name}. Please ensure '

    ValueError: Unknown loss function: sparse. Please ensure this object is passed to the `custom_objects` argument. See https://www.tensorflow.org/guide/keras/save_and_serialize#registering_the_custom_object for details.
Traceback (most recent call last):
  File "src/01_base_model_creation.py", line 82, in <module>
    main(config_path=parsed_args.config)
  File "src/01_base_model_creation.py", line 62, in main
    verbose=1)
  File "C:\Users\Sasmitabhoi\anaconda3\envs\Transfer-Learning\lib\site-packages\keras\utils\traceback_utils.py", line 67, in error_handler
    raise e.with_traceback(filtered_tb) from None
  File "C:\Users\Sasmitabhoi\anaconda3\envs\Transfer-Learning\lib\site-packages\tensorflow\python\framework\func_graph.py", line 1129, in autograph_handler
    raise e.ag_error_metadata.to_exception(e)
ValueError: in user code:

    File "C:\Users\Sasmitabhoi\anaconda3\envs\Transfer-Learning\lib\site-packages\keras\engine\training.py", line 878, in train_function  *
        return step_function(self, iterator)
    File "C:\Users\Sasmitabhoi\anaconda3\envs\Transfer-Learning\lib\site-packages\keras\engine\training.py", line 867, in step_function  **
        outputs = model.distribute_strategy.run(run_step, args=(data,))
    File "C:\Users\Sasmitabhoi\anaconda3\envs\Transfer-Learning\lib\site-packages\keras\engine\training.py", line 860, in run_step  **
        outputs = model.train_step(data)
    File "C:\Users\Sasmitabhoi\anaconda3\envs\Transfer-Learning\lib\site-packages\keras\engine\training.py", line 810, in train_step
        y, y_pred, sample_weight, regularization_losses=self.losses)
    File "C:\Users\Sasmitabhoi\anaconda3\envs\Transfer-Learning\lib\site-packages\keras\engine\compile_utils.py", line 184, in __call__
        self.build(y_pred)
    File "C:\Users\Sasmitabhoi\anaconda3\envs\Transfer-Learning\lib\site-packages\keras\engine\compile_utils.py", line 133, in build
        self._losses = tf.nest.map_structure(self._get_loss_object, self._losses)
    File "C:\Users\Sasmitabhoi\anaconda3\envs\Transfer-Learning\lib\site-packages\keras\engine\compile_utils.py", line 273, in _get_loss_object
        loss = losses_mod.get(loss)
    File "C:\Users\Sasmitabhoi\anaconda3\envs\Transfer-Learning\lib\site-packages\keras\losses.py", line 2134, in get
        return deserialize(identifier)
    File "C:\Users\Sasmitabhoi\anaconda3\envs\Transfer-Learning\lib\site-packages\keras\losses.py", line 2093, in deserialize
        printable_module_name='loss function')
    File "C:\Users\Sasmitabhoi\anaconda3\envs\Transfer-Learning\lib\site-packages\keras\utils\generic_utils.py", line 709, in deserialize_keras_object
        f'Unknown {printable_module_name}: {object_name}. Please ensure '

    ValueError: Unknown loss function: sparse. Please ensure this object is passed to the `custom_objects` argument. See https://www.tensorflow.org/guide/keras/save_and_serialize#registering_the_custom_object for details.

[2021-11-21 11:40:18,498: INFO: 01_base_model_creation]: 
********************
[2021-11-21 11:40:18,499: INFO: 01_base_model_creation]: >>>>> stage creating base model started <<<<<
[2021-11-21 11:40:18,501: INFO: common]: yaml file: configs/config.yaml loaded successfully
[2021-11-21 11:40:44,508: ERROR: 01_base_model_creation]: in user code:

    File "C:\Users\Sasmitabhoi\anaconda3\envs\Transfer-Learning\lib\site-packages\keras\engine\training.py", line 878, in train_function  *
        return step_function(self, iterator)
    File "C:\Users\Sasmitabhoi\anaconda3\envs\Transfer-Learning\lib\site-packages\keras\engine\training.py", line 867, in step_function  **
        outputs = model.distribute_strategy.run(run_step, args=(data,))
    File "C:\Users\Sasmitabhoi\anaconda3\envs\Transfer-Learning\lib\site-packages\keras\engine\training.py", line 860, in run_step  **
        outputs = model.train_step(data)
    File "C:\Users\Sasmitabhoi\anaconda3\envs\Transfer-Learning\lib\site-packages\keras\engine\training.py", line 810, in train_step
        y, y_pred, sample_weight, regularization_losses=self.losses)
    File "C:\Users\Sasmitabhoi\anaconda3\envs\Transfer-Learning\lib\site-packages\keras\engine\compile_utils.py", line 184, in __call__
        self.build(y_pred)
    File "C:\Users\Sasmitabhoi\anaconda3\envs\Transfer-Learning\lib\site-packages\keras\engine\compile_utils.py", line 133, in build
        self._losses = tf.nest.map_structure(self._get_loss_object, self._losses)
    File "C:\Users\Sasmitabhoi\anaconda3\envs\Transfer-Learning\lib\site-packages\keras\engine\compile_utils.py", line 273, in _get_loss_object
        loss = losses_mod.get(loss)
    File "C:\Users\Sasmitabhoi\anaconda3\envs\Transfer-Learning\lib\site-packages\keras\losses.py", line 2134, in get
        return deserialize(identifier)
    File "C:\Users\Sasmitabhoi\anaconda3\envs\Transfer-Learning\lib\site-packages\keras\losses.py", line 2093, in deserialize
        printable_module_name='loss function')
    File "C:\Users\Sasmitabhoi\anaconda3\envs\Transfer-Learning\lib\site-packages\keras\utils\generic_utils.py", line 709, in deserialize_keras_object
        f'Unknown {printable_module_name}: {object_name}. Please ensure '

    ValueError: Unknown loss function: sparse. Please ensure this object is passed to the `custom_objects` argument. See https://www.tensorflow.org/guide/keras/save_and_serialize#registering_the_custom_object for details.
Traceback (most recent call last):
  File "src/01_base_model_creation.py", line 82, in <module>
    main(config_path=parsed_args.config)
  File "src/01_base_model_creation.py", line 61, in main
    validation_data=(X_valid,y_valid),
  File "C:\Users\Sasmitabhoi\anaconda3\envs\Transfer-Learning\lib\site-packages\keras\utils\traceback_utils.py", line 67, in error_handler
    raise e.with_traceback(filtered_tb) from None
  File "C:\Users\Sasmitabhoi\anaconda3\envs\Transfer-Learning\lib\site-packages\tensorflow\python\framework\func_graph.py", line 1129, in autograph_handler
    raise e.ag_error_metadata.to_exception(e)
ValueError: in user code:

    File "C:\Users\Sasmitabhoi\anaconda3\envs\Transfer-Learning\lib\site-packages\keras\engine\training.py", line 878, in train_function  *
        return step_function(self, iterator)
    File "C:\Users\Sasmitabhoi\anaconda3\envs\Transfer-Learning\lib\site-packages\keras\engine\training.py", line 867, in step_function  **
        outputs = model.distribute_strategy.run(run_step, args=(data,))
    File "C:\Users\Sasmitabhoi\anaconda3\envs\Transfer-Learning\lib\site-packages\keras\engine\training.py", line 860, in run_step  **
        outputs = model.train_step(data)
    File "C:\Users\Sasmitabhoi\anaconda3\envs\Transfer-Learning\lib\site-packages\keras\engine\training.py", line 810, in train_step
        y, y_pred, sample_weight, regularization_losses=self.losses)
    File "C:\Users\Sasmitabhoi\anaconda3\envs\Transfer-Learning\lib\site-packages\keras\engine\compile_utils.py", line 184, in __call__
        self.build(y_pred)
    File "C:\Users\Sasmitabhoi\anaconda3\envs\Transfer-Learning\lib\site-packages\keras\engine\compile_utils.py", line 133, in build
        self._losses = tf.nest.map_structure(self._get_loss_object, self._losses)
    File "C:\Users\Sasmitabhoi\anaconda3\envs\Transfer-Learning\lib\site-packages\keras\engine\compile_utils.py", line 273, in _get_loss_object
        loss = losses_mod.get(loss)
    File "C:\Users\Sasmitabhoi\anaconda3\envs\Transfer-Learning\lib\site-packages\keras\losses.py", line 2134, in get
        return deserialize(identifier)
    File "C:\Users\Sasmitabhoi\anaconda3\envs\Transfer-Learning\lib\site-packages\keras\losses.py", line 2093, in deserialize
        printable_module_name='loss function')
    File "C:\Users\Sasmitabhoi\anaconda3\envs\Transfer-Learning\lib\site-packages\keras\utils\generic_utils.py", line 709, in deserialize_keras_object
        f'Unknown {printable_module_name}: {object_name}. Please ensure '

    ValueError: Unknown loss function: sparse. Please ensure this object is passed to the `custom_objects` argument. See https://www.tensorflow.org/guide/keras/save_and_serialize#registering_the_custom_object for details.

[2021-11-21 11:41:15,430: INFO: 01_base_model_creation]: 
********************
[2021-11-21 11:41:15,430: INFO: 01_base_model_creation]: >>>>> stage creating base model started <<<<<
[2021-11-21 11:41:15,433: INFO: common]: yaml file: configs/config.yaml loaded successfully
[2021-11-21 11:41:18,220: ERROR: 01_base_model_creation]: in user code:

    File "C:\Users\Sasmitabhoi\anaconda3\envs\Transfer-Learning\lib\site-packages\keras\engine\training.py", line 878, in train_function  *
        return step_function(self, iterator)
    File "C:\Users\Sasmitabhoi\anaconda3\envs\Transfer-Learning\lib\site-packages\keras\engine\training.py", line 867, in step_function  **
        outputs = model.distribute_strategy.run(run_step, args=(data,))
    File "C:\Users\Sasmitabhoi\anaconda3\envs\Transfer-Learning\lib\site-packages\keras\engine\training.py", line 860, in run_step  **
        outputs = model.train_step(data)
    File "C:\Users\Sasmitabhoi\anaconda3\envs\Transfer-Learning\lib\site-packages\keras\engine\training.py", line 810, in train_step
        y, y_pred, sample_weight, regularization_losses=self.losses)
    File "C:\Users\Sasmitabhoi\anaconda3\envs\Transfer-Learning\lib\site-packages\keras\engine\compile_utils.py", line 184, in __call__
        self.build(y_pred)
    File "C:\Users\Sasmitabhoi\anaconda3\envs\Transfer-Learning\lib\site-packages\keras\engine\compile_utils.py", line 133, in build
        self._losses = tf.nest.map_structure(self._get_loss_object, self._losses)
    File "C:\Users\Sasmitabhoi\anaconda3\envs\Transfer-Learning\lib\site-packages\keras\engine\compile_utils.py", line 273, in _get_loss_object
        loss = losses_mod.get(loss)
    File "C:\Users\Sasmitabhoi\anaconda3\envs\Transfer-Learning\lib\site-packages\keras\losses.py", line 2134, in get
        return deserialize(identifier)
    File "C:\Users\Sasmitabhoi\anaconda3\envs\Transfer-Learning\lib\site-packages\keras\losses.py", line 2093, in deserialize
        printable_module_name='loss function')
    File "C:\Users\Sasmitabhoi\anaconda3\envs\Transfer-Learning\lib\site-packages\keras\utils\generic_utils.py", line 709, in deserialize_keras_object
        f'Unknown {printable_module_name}: {object_name}. Please ensure '

    ValueError: Unknown loss function: sparse. Please ensure this object is passed to the `custom_objects` argument. See https://www.tensorflow.org/guide/keras/save_and_serialize#registering_the_custom_object for details.
Traceback (most recent call last):
  File "src/01_base_model_creation.py", line 82, in <module>
    main(config_path=parsed_args.config)
  File "src/01_base_model_creation.py", line 61, in main
    validation_data=(X_valid,y_valid)
  File "C:\Users\Sasmitabhoi\anaconda3\envs\Transfer-Learning\lib\site-packages\keras\utils\traceback_utils.py", line 67, in error_handler
    raise e.with_traceback(filtered_tb) from None
  File "C:\Users\Sasmitabhoi\anaconda3\envs\Transfer-Learning\lib\site-packages\tensorflow\python\framework\func_graph.py", line 1129, in autograph_handler
    raise e.ag_error_metadata.to_exception(e)
ValueError: in user code:

    File "C:\Users\Sasmitabhoi\anaconda3\envs\Transfer-Learning\lib\site-packages\keras\engine\training.py", line 878, in train_function  *
        return step_function(self, iterator)
    File "C:\Users\Sasmitabhoi\anaconda3\envs\Transfer-Learning\lib\site-packages\keras\engine\training.py", line 867, in step_function  **
        outputs = model.distribute_strategy.run(run_step, args=(data,))
    File "C:\Users\Sasmitabhoi\anaconda3\envs\Transfer-Learning\lib\site-packages\keras\engine\training.py", line 860, in run_step  **
        outputs = model.train_step(data)
    File "C:\Users\Sasmitabhoi\anaconda3\envs\Transfer-Learning\lib\site-packages\keras\engine\training.py", line 810, in train_step
        y, y_pred, sample_weight, regularization_losses=self.losses)
    File "C:\Users\Sasmitabhoi\anaconda3\envs\Transfer-Learning\lib\site-packages\keras\engine\compile_utils.py", line 184, in __call__
        self.build(y_pred)
    File "C:\Users\Sasmitabhoi\anaconda3\envs\Transfer-Learning\lib\site-packages\keras\engine\compile_utils.py", line 133, in build
        self._losses = tf.nest.map_structure(self._get_loss_object, self._losses)
    File "C:\Users\Sasmitabhoi\anaconda3\envs\Transfer-Learning\lib\site-packages\keras\engine\compile_utils.py", line 273, in _get_loss_object
        loss = losses_mod.get(loss)
    File "C:\Users\Sasmitabhoi\anaconda3\envs\Transfer-Learning\lib\site-packages\keras\losses.py", line 2134, in get
        return deserialize(identifier)
    File "C:\Users\Sasmitabhoi\anaconda3\envs\Transfer-Learning\lib\site-packages\keras\losses.py", line 2093, in deserialize
        printable_module_name='loss function')
    File "C:\Users\Sasmitabhoi\anaconda3\envs\Transfer-Learning\lib\site-packages\keras\utils\generic_utils.py", line 709, in deserialize_keras_object
        f'Unknown {printable_module_name}: {object_name}. Please ensure '

    ValueError: Unknown loss function: sparse. Please ensure this object is passed to the `custom_objects` argument. See https://www.tensorflow.org/guide/keras/save_and_serialize#registering_the_custom_object for details.

[2021-11-21 11:43:16,491: INFO: 01_base_model_creation]: 
********************
[2021-11-21 11:43:16,492: INFO: 01_base_model_creation]: >>>>> stage creating base model started <<<<<
[2021-11-21 11:43:16,495: INFO: common]: yaml file: configs/config.yaml loaded successfully
[2021-11-21 11:43:19,274: ERROR: 01_base_model_creation]: in user code:

    File "C:\Users\Sasmitabhoi\anaconda3\envs\Transfer-Learning\lib\site-packages\keras\engine\training.py", line 878, in train_function  *
        return step_function(self, iterator)
    File "C:\Users\Sasmitabhoi\anaconda3\envs\Transfer-Learning\lib\site-packages\keras\engine\training.py", line 867, in step_function  **
        outputs = model.distribute_strategy.run(run_step, args=(data,))
    File "C:\Users\Sasmitabhoi\anaconda3\envs\Transfer-Learning\lib\site-packages\keras\engine\training.py", line 860, in run_step  **
        outputs = model.train_step(data)
    File "C:\Users\Sasmitabhoi\anaconda3\envs\Transfer-Learning\lib\site-packages\keras\engine\training.py", line 810, in train_step
        y, y_pred, sample_weight, regularization_losses=self.losses)
    File "C:\Users\Sasmitabhoi\anaconda3\envs\Transfer-Learning\lib\site-packages\keras\engine\compile_utils.py", line 184, in __call__
        self.build(y_pred)
    File "C:\Users\Sasmitabhoi\anaconda3\envs\Transfer-Learning\lib\site-packages\keras\engine\compile_utils.py", line 133, in build
        self._losses = tf.nest.map_structure(self._get_loss_object, self._losses)
    File "C:\Users\Sasmitabhoi\anaconda3\envs\Transfer-Learning\lib\site-packages\keras\engine\compile_utils.py", line 273, in _get_loss_object
        loss = losses_mod.get(loss)
    File "C:\Users\Sasmitabhoi\anaconda3\envs\Transfer-Learning\lib\site-packages\keras\losses.py", line 2134, in get
        return deserialize(identifier)
    File "C:\Users\Sasmitabhoi\anaconda3\envs\Transfer-Learning\lib\site-packages\keras\losses.py", line 2093, in deserialize
        printable_module_name='loss function')
    File "C:\Users\Sasmitabhoi\anaconda3\envs\Transfer-Learning\lib\site-packages\keras\utils\generic_utils.py", line 709, in deserialize_keras_object
        f'Unknown {printable_module_name}: {object_name}. Please ensure '

    ValueError: Unknown loss function: sparse. Please ensure this object is passed to the `custom_objects` argument. See https://www.tensorflow.org/guide/keras/save_and_serialize#registering_the_custom_object for details.
Traceback (most recent call last):
  File "src/01_base_model_creation.py", line 83, in <module>
    main(config_path=parsed_args.config)
  File "src/01_base_model_creation.py", line 62, in main
    verbose=2)
  File "C:\Users\Sasmitabhoi\anaconda3\envs\Transfer-Learning\lib\site-packages\keras\utils\traceback_utils.py", line 67, in error_handler
    raise e.with_traceback(filtered_tb) from None
  File "C:\Users\Sasmitabhoi\anaconda3\envs\Transfer-Learning\lib\site-packages\tensorflow\python\framework\func_graph.py", line 1129, in autograph_handler
    raise e.ag_error_metadata.to_exception(e)
ValueError: in user code:

    File "C:\Users\Sasmitabhoi\anaconda3\envs\Transfer-Learning\lib\site-packages\keras\engine\training.py", line 878, in train_function  *
        return step_function(self, iterator)
    File "C:\Users\Sasmitabhoi\anaconda3\envs\Transfer-Learning\lib\site-packages\keras\engine\training.py", line 867, in step_function  **
        outputs = model.distribute_strategy.run(run_step, args=(data,))
    File "C:\Users\Sasmitabhoi\anaconda3\envs\Transfer-Learning\lib\site-packages\keras\engine\training.py", line 860, in run_step  **
        outputs = model.train_step(data)
    File "C:\Users\Sasmitabhoi\anaconda3\envs\Transfer-Learning\lib\site-packages\keras\engine\training.py", line 810, in train_step
        y, y_pred, sample_weight, regularization_losses=self.losses)
    File "C:\Users\Sasmitabhoi\anaconda3\envs\Transfer-Learning\lib\site-packages\keras\engine\compile_utils.py", line 184, in __call__
        self.build(y_pred)
    File "C:\Users\Sasmitabhoi\anaconda3\envs\Transfer-Learning\lib\site-packages\keras\engine\compile_utils.py", line 133, in build
        self._losses = tf.nest.map_structure(self._get_loss_object, self._losses)
    File "C:\Users\Sasmitabhoi\anaconda3\envs\Transfer-Learning\lib\site-packages\keras\engine\compile_utils.py", line 273, in _get_loss_object
        loss = losses_mod.get(loss)
    File "C:\Users\Sasmitabhoi\anaconda3\envs\Transfer-Learning\lib\site-packages\keras\losses.py", line 2134, in get
        return deserialize(identifier)
    File "C:\Users\Sasmitabhoi\anaconda3\envs\Transfer-Learning\lib\site-packages\keras\losses.py", line 2093, in deserialize
        printable_module_name='loss function')
    File "C:\Users\Sasmitabhoi\anaconda3\envs\Transfer-Learning\lib\site-packages\keras\utils\generic_utils.py", line 709, in deserialize_keras_object
        f'Unknown {printable_module_name}: {object_name}. Please ensure '

    ValueError: Unknown loss function: sparse. Please ensure this object is passed to the `custom_objects` argument. See https://www.tensorflow.org/guide/keras/save_and_serialize#registering_the_custom_object for details.

[2021-11-21 11:44:57,930: INFO: 01_base_model_creation]: 
********************
[2021-11-21 11:44:57,930: INFO: 01_base_model_creation]: >>>>> stage creating base model started <<<<<
[2021-11-21 11:44:57,932: INFO: common]: yaml file: configs/config.yaml loaded successfully
[2021-11-21 11:45:00,774: ERROR: 01_base_model_creation]: in user code:

    File "C:\Users\Sasmitabhoi\anaconda3\envs\Transfer-Learning\lib\site-packages\keras\engine\training.py", line 878, in train_function  *
        return step_function(self, iterator)
    File "C:\Users\Sasmitabhoi\anaconda3\envs\Transfer-Learning\lib\site-packages\keras\engine\training.py", line 867, in step_function  **
        outputs = model.distribute_strategy.run(run_step, args=(data,))
    File "C:\Users\Sasmitabhoi\anaconda3\envs\Transfer-Learning\lib\site-packages\keras\engine\training.py", line 860, in run_step  **
        outputs = model.train_step(data)
    File "C:\Users\Sasmitabhoi\anaconda3\envs\Transfer-Learning\lib\site-packages\keras\engine\training.py", line 810, in train_step
        y, y_pred, sample_weight, regularization_losses=self.losses)
    File "C:\Users\Sasmitabhoi\anaconda3\envs\Transfer-Learning\lib\site-packages\keras\engine\compile_utils.py", line 184, in __call__
        self.build(y_pred)
    File "C:\Users\Sasmitabhoi\anaconda3\envs\Transfer-Learning\lib\site-packages\keras\engine\compile_utils.py", line 133, in build
        self._losses = tf.nest.map_structure(self._get_loss_object, self._losses)
    File "C:\Users\Sasmitabhoi\anaconda3\envs\Transfer-Learning\lib\site-packages\keras\engine\compile_utils.py", line 273, in _get_loss_object
        loss = losses_mod.get(loss)
    File "C:\Users\Sasmitabhoi\anaconda3\envs\Transfer-Learning\lib\site-packages\keras\losses.py", line 2134, in get
        return deserialize(identifier)
    File "C:\Users\Sasmitabhoi\anaconda3\envs\Transfer-Learning\lib\site-packages\keras\losses.py", line 2093, in deserialize
        printable_module_name='loss function')
    File "C:\Users\Sasmitabhoi\anaconda3\envs\Transfer-Learning\lib\site-packages\keras\utils\generic_utils.py", line 709, in deserialize_keras_object
        f'Unknown {printable_module_name}: {object_name}. Please ensure '

    ValueError: Unknown loss function: sparse. Please ensure this object is passed to the `custom_objects` argument. See https://www.tensorflow.org/guide/keras/save_and_serialize#registering_the_custom_object for details.
Traceback (most recent call last):
  File "src/01_base_model_creation.py", line 83, in <module>
    main(config_path=parsed_args.config)
  File "src/01_base_model_creation.py", line 62, in main
    verbose=2)
  File "C:\Users\Sasmitabhoi\anaconda3\envs\Transfer-Learning\lib\site-packages\keras\utils\traceback_utils.py", line 67, in error_handler
    raise e.with_traceback(filtered_tb) from None
  File "C:\Users\Sasmitabhoi\anaconda3\envs\Transfer-Learning\lib\site-packages\tensorflow\python\framework\func_graph.py", line 1129, in autograph_handler
    raise e.ag_error_metadata.to_exception(e)
ValueError: in user code:

    File "C:\Users\Sasmitabhoi\anaconda3\envs\Transfer-Learning\lib\site-packages\keras\engine\training.py", line 878, in train_function  *
        return step_function(self, iterator)
    File "C:\Users\Sasmitabhoi\anaconda3\envs\Transfer-Learning\lib\site-packages\keras\engine\training.py", line 867, in step_function  **
        outputs = model.distribute_strategy.run(run_step, args=(data,))
    File "C:\Users\Sasmitabhoi\anaconda3\envs\Transfer-Learning\lib\site-packages\keras\engine\training.py", line 860, in run_step  **
        outputs = model.train_step(data)
    File "C:\Users\Sasmitabhoi\anaconda3\envs\Transfer-Learning\lib\site-packages\keras\engine\training.py", line 810, in train_step
        y, y_pred, sample_weight, regularization_losses=self.losses)
    File "C:\Users\Sasmitabhoi\anaconda3\envs\Transfer-Learning\lib\site-packages\keras\engine\compile_utils.py", line 184, in __call__
        self.build(y_pred)
    File "C:\Users\Sasmitabhoi\anaconda3\envs\Transfer-Learning\lib\site-packages\keras\engine\compile_utils.py", line 133, in build
        self._losses = tf.nest.map_structure(self._get_loss_object, self._losses)
    File "C:\Users\Sasmitabhoi\anaconda3\envs\Transfer-Learning\lib\site-packages\keras\engine\compile_utils.py", line 273, in _get_loss_object
        loss = losses_mod.get(loss)
    File "C:\Users\Sasmitabhoi\anaconda3\envs\Transfer-Learning\lib\site-packages\keras\losses.py", line 2134, in get
        return deserialize(identifier)
    File "C:\Users\Sasmitabhoi\anaconda3\envs\Transfer-Learning\lib\site-packages\keras\losses.py", line 2093, in deserialize
        printable_module_name='loss function')
    File "C:\Users\Sasmitabhoi\anaconda3\envs\Transfer-Learning\lib\site-packages\keras\utils\generic_utils.py", line 709, in deserialize_keras_object
        f'Unknown {printable_module_name}: {object_name}. Please ensure '

    ValueError: Unknown loss function: sparse. Please ensure this object is passed to the `custom_objects` argument. See https://www.tensorflow.org/guide/keras/save_and_serialize#registering_the_custom_object for details.

